Watching for file changes with StatReloader
CommandError: "0.0.0.0.:5100" is not a valid port number or address:port pair.
CommandError: "0.0.0.0.:5100" is not a valid port number or address:port pair.
Watching for file changes with StatReloader
Watching for file changes with StatReloader
Invalid HTTP_HOST header: '13.211.97.129:5100'. You may need to add '13.211.97.129' to ALLOWED_HOSTS.
Bad Request: /
[24/Feb/2021 20:17:40] "GET / HTTP/1.1" 400 62940
/home/centos/invoicing/invoicing/src/invoicing/settings.py changed, reloading.
Performing system checks...

System check identified no issues (0 silenced).

You have 25 unapplied migration(s). Your project may not work properly until you apply the migrations for app(s): django_celery_beat, django_celery_results.
Run 'python manage.py migrate' to apply them.
February 24, 2021 - 20:17:35
Django version 3.1.7, using settings 'invoicing.settings'
Starting development server at http://0.0.0.0:5100/
Quit the server with CONTROL-C.
Traceback (most recent call last):
  File "manage.py", line 22, in <module>
    main()
  File "manage.py", line 18, in main
    execute_from_command_line(sys.argv)
  File "/usr/local/lib/python3.6/site-packages/django/core/management/__init__.py", line 401, in execute_from_command_line
    utility.execute()
  File "/usr/local/lib/python3.6/site-packages/django/core/management/__init__.py", line 345, in execute
    settings.INSTALLED_APPS
  File "/usr/local/lib/python3.6/site-packages/django/conf/__init__.py", line 82, in __getattr__
    self._setup(name)
  File "/usr/local/lib/python3.6/site-packages/django/conf/__init__.py", line 69, in _setup
    self._wrapped = Settings(settings_module)
  File "/usr/local/lib/python3.6/site-packages/django/conf/__init__.py", line 170, in __init__
    mod = importlib.import_module(self.SETTINGS_MODULE)
  File "/usr/lib64/python3.6/importlib/__init__.py", line 126, in import_module
    return _bootstrap._gcd_import(name[level:], package, level)
  File "<frozen importlib._bootstrap>", line 994, in _gcd_import
  File "<frozen importlib._bootstrap>", line 971, in _find_and_load
  File "<frozen importlib._bootstrap>", line 941, in _find_and_load_unlocked
  File "<frozen importlib._bootstrap>", line 219, in _call_with_frames_removed
  File "<frozen importlib._bootstrap>", line 994, in _gcd_import
  File "<frozen importlib._bootstrap>", line 971, in _find_and_load
  File "<frozen importlib._bootstrap>", line 955, in _find_and_load_unlocked
  File "<frozen importlib._bootstrap>", line 665, in _load_unlocked
  File "<frozen importlib._bootstrap_external>", line 678, in exec_module
  File "<frozen importlib._bootstrap>", line 219, in _call_with_frames_removed
  File "/home/centos/invoicing/invoicing/src/invoicing/__init__.py", line 1, in <module>
    from .celery import app as celery_app 
  File "/home/centos/invoicing/invoicing/src/invoicing/celery.py", line 43, in <module>
    file_path   = os.path.join(os.path.dirname(settings.BASE_DIR), "src")
  File "/usr/local/lib/python3.6/site-packages/django/conf/__init__.py", line 82, in __getattr__
    self._setup(name)
  File "/usr/local/lib/python3.6/site-packages/django/conf/__init__.py", line 69, in _setup
    self._wrapped = Settings(settings_module)
  File "/usr/local/lib/python3.6/site-packages/django/conf/__init__.py", line 170, in __init__
    mod = importlib.import_module(self.SETTINGS_MODULE)
  File "/usr/lib64/python3.6/importlib/__init__.py", line 126, in import_module
    return _bootstrap._gcd_import(name[level:], package, level)
  File "/home/centos/invoicing/invoicing/src/invoicing/settings.py", line 28
    ALLOWED_HOSTS = [13.211.97.129]
                             ^
SyntaxError: invalid syntax
Watching for file changes with StatReloader
Not Found: /
[24/Feb/2021 20:19:41] "GET / HTTP/1.1" 404 2052
[24/Feb/2021 20:19:53] "GET /admin HTTP/1.1" 301 0
Session data corrupted
[24/Feb/2021 20:19:54] "GET /admin/ HTTP/1.1" 302 0
Session data corrupted
[24/Feb/2021 20:19:54] "GET /admin/login/?next=/admin/ HTTP/1.1" 200 2194
[24/Feb/2021 20:19:55] "GET /static/admin/css/base.css HTTP/1.1" 200 16307
[24/Feb/2021 20:19:55] "GET /static/admin/css/nav_sidebar.css HTTP/1.1" 200 2138
[24/Feb/2021 20:19:55] "GET /static/admin/css/login.css HTTP/1.1" 200 1185
[24/Feb/2021 20:19:55] "GET /static/admin/css/responsive.css HTTP/1.1" 200 18344
[24/Feb/2021 20:19:55] "GET /static/admin/js/nav_sidebar.js HTTP/1.1" 200 1360
[24/Feb/2021 20:19:56] "GET /static/admin/css/fonts.css HTTP/1.1" 200 423
[24/Feb/2021 20:19:57] "GET /static/admin/fonts/Roboto-Regular-webfont.woff HTTP/1.1" 200 85876
[24/Feb/2021 20:19:57] "GET /static/admin/fonts/Roboto-Light-webfont.woff HTTP/1.1" 200 85692
Session data corrupted
[24/Feb/2021 20:20:12] "POST /admin/login/?next=/admin/ HTTP/1.1" 302 0
[24/Feb/2021 20:20:12] "GET /admin/ HTTP/1.1" 200 7399
[24/Feb/2021 20:20:13] "GET /static/admin/css/dashboard.css HTTP/1.1" 200 380
[24/Feb/2021 20:20:13] "GET /static/admin/img/icon-addlink.svg HTTP/1.1" 200 331
[24/Feb/2021 20:20:13] "GET /static/admin/img/icon-changelink.svg HTTP/1.1" 200 380
[24/Feb/2021 20:20:13] "GET /static/admin/fonts/Roboto-Bold-webfont.woff HTTP/1.1" 200 86184
Not Found: /favicon.ico
[24/Feb/2021 20:20:14] "GET /favicon.ico HTTP/1.1" 404 2103
Internal Server Error: /admin/django_celery_beat/periodictask/
Traceback (most recent call last):
  File "/usr/local/lib/python3.6/site-packages/django/db/backends/utils.py", line 84, in _execute
    return self.cursor.execute(sql, params)
  File "/usr/local/lib/python3.6/site-packages/django/db/backends/mysql/base.py", line 73, in execute
    return self.cursor.execute(query, args)
  File "/usr/local/lib64/python3.6/site-packages/MySQLdb/cursors.py", line 206, in execute
    res = self._query(query)
  File "/usr/local/lib64/python3.6/site-packages/MySQLdb/cursors.py", line 319, in _query
    db.query(q)
  File "/usr/local/lib64/python3.6/site-packages/MySQLdb/connections.py", line 259, in query
    _mysql.connection.query(self, query)
MySQLdb._exceptions.ProgrammingError: (1146, "Table 'NewHazSydWater.django_celery_beat_periodictask' doesn't exist")

The above exception was the direct cause of the following exception:

Traceback (most recent call last):
  File "/usr/local/lib/python3.6/site-packages/django/core/handlers/exception.py", line 47, in inner
    response = get_response(request)
  File "/usr/local/lib/python3.6/site-packages/django/core/handlers/base.py", line 181, in _get_response
    response = wrapped_callback(request, *callback_args, **callback_kwargs)
  File "/usr/local/lib/python3.6/site-packages/django/contrib/admin/options.py", line 614, in wrapper
    return self.admin_site.admin_view(view)(*args, **kwargs)
  File "/usr/local/lib/python3.6/site-packages/django/utils/decorators.py", line 130, in _wrapped_view
    response = view_func(request, *args, **kwargs)
  File "/usr/local/lib/python3.6/site-packages/django/views/decorators/cache.py", line 44, in _wrapped_view_func
    response = view_func(request, *args, **kwargs)
  File "/usr/local/lib/python3.6/site-packages/django/contrib/admin/sites.py", line 233, in inner
    return view(request, *args, **kwargs)
  File "/usr/local/lib/python3.6/site-packages/django_celery_beat/admin.py", line 153, in changelist_view
    request, extra_context)
  File "/usr/local/lib/python3.6/site-packages/django/utils/decorators.py", line 43, in _wrapper
    return bound_method(*args, **kwargs)
  File "/usr/local/lib/python3.6/site-packages/django/utils/decorators.py", line 130, in _wrapped_view
    response = view_func(request, *args, **kwargs)
  File "/usr/local/lib/python3.6/site-packages/django/contrib/admin/options.py", line 1693, in changelist_view
    cl = self.get_changelist_instance(request)
  File "/usr/local/lib/python3.6/site-packages/django/contrib/admin/options.py", line 748, in get_changelist_instance
    sortable_by,
  File "/usr/local/lib/python3.6/site-packages/django/contrib/admin/views/main.py", line 100, in __init__
    self.get_results(request)
  File "/usr/local/lib/python3.6/site-packages/django/contrib/admin/views/main.py", line 235, in get_results
    result_count = paginator.count
  File "/usr/local/lib/python3.6/site-packages/django/utils/functional.py", line 48, in __get__
    res = instance.__dict__[self.name] = self.func(instance)
  File "/usr/local/lib/python3.6/site-packages/django/core/paginator.py", line 94, in count
    return c()
  File "/usr/local/lib/python3.6/site-packages/django/db/models/query.py", line 411, in count
    return self.query.get_count(using=self.db)
  File "/usr/local/lib/python3.6/site-packages/django/db/models/sql/query.py", line 515, in get_count
    number = obj.get_aggregation(using, ['__count'])['__count']
  File "/usr/local/lib/python3.6/site-packages/django/db/models/sql/query.py", line 500, in get_aggregation
    result = compiler.execute_sql(SINGLE)
  File "/usr/local/lib/python3.6/site-packages/django/db/models/sql/compiler.py", line 1156, in execute_sql
    cursor.execute(sql, params)
  File "/usr/local/lib/python3.6/site-packages/django/db/backends/utils.py", line 98, in execute
    return super().execute(sql, params)
  File "/usr/local/lib/python3.6/site-packages/django/db/backends/utils.py", line 66, in execute
    return self._execute_with_wrappers(sql, params, many=False, executor=self._execute)
  File "/usr/local/lib/python3.6/site-packages/django/db/backends/utils.py", line 75, in _execute_with_wrappers
    return executor(sql, params, many, context)
  File "/usr/local/lib/python3.6/site-packages/django/db/backends/utils.py", line 84, in _execute
    return self.cursor.execute(sql, params)
  File "/usr/local/lib/python3.6/site-packages/django/db/utils.py", line 90, in __exit__
    raise dj_exc_value.with_traceback(traceback) from exc_value
  File "/usr/local/lib/python3.6/site-packages/django/db/backends/utils.py", line 84, in _execute
    return self.cursor.execute(sql, params)
  File "/usr/local/lib/python3.6/site-packages/django/db/backends/mysql/base.py", line 73, in execute
    return self.cursor.execute(query, args)
  File "/usr/local/lib64/python3.6/site-packages/MySQLdb/cursors.py", line 206, in execute
    res = self._query(query)
  File "/usr/local/lib64/python3.6/site-packages/MySQLdb/cursors.py", line 319, in _query
    db.query(q)
  File "/usr/local/lib64/python3.6/site-packages/MySQLdb/connections.py", line 259, in query
    _mysql.connection.query(self, query)
django.db.utils.ProgrammingError: (1146, "Table 'NewHazSydWater.django_celery_beat_periodictask' doesn't exist")
[24/Feb/2021 20:20:31] "GET /admin/django_celery_beat/periodictask/ HTTP/1.1" 500 200208
Not Found: /favicon.ico
[24/Feb/2021 20:20:33] "GET /favicon.ico HTTP/1.1" 404 2103
/usr/local/lib/python3.6/site-packages/django/contrib/auth/forms.py changed, reloading.
Performing system checks...

System check identified no issues (0 silenced).

You have 25 unapplied migration(s). Your project may not work properly until you apply the migrations for app(s): django_celery_beat, django_celery_results.
Run 'python manage.py migrate' to apply them.
February 24, 2021 - 20:19:37
Django version 3.1.7, using settings 'invoicing.settings'
Starting development server at http://0.0.0.0:5100/
Quit the server with CONTROL-C.
Watching for file changes with StatReloader
Exception in thread django-main-thread:
Traceback (most recent call last):
  File "/usr/lib64/python3.6/threading.py", line 916, in _bootstrap_inner
    self.run()
  File "/usr/lib64/python3.6/threading.py", line 864, in run
    self._target(*self._args, **self._kwargs)
  File "/usr/local/lib/python3.6/site-packages/django/utils/autoreload.py", line 53, in wrapper
    fn(*args, **kwargs)
  File "/usr/local/lib/python3.6/site-packages/django/core/management/commands/runserver.py", line 110, in inner_run
    autoreload.raise_last_exception()
  File "/usr/local/lib/python3.6/site-packages/django/utils/autoreload.py", line 76, in raise_last_exception
    raise _exception[1]
  File "/usr/local/lib/python3.6/site-packages/django/core/management/__init__.py", line 357, in execute
    autoreload.check_errors(django.setup)()
  File "/usr/local/lib/python3.6/site-packages/django/utils/autoreload.py", line 53, in wrapper
    fn(*args, **kwargs)
  File "/usr/local/lib/python3.6/site-packages/django/__init__.py", line 24, in setup
    apps.populate(settings.INSTALLED_APPS)
  File "/usr/local/lib/python3.6/site-packages/django/apps/registry.py", line 122, in populate
    app_config.ready()
  File "/usr/local/lib/python3.6/site-packages/django/contrib/admin/apps.py", line 24, in ready
    self.module.autodiscover()
  File "/usr/local/lib/python3.6/site-packages/django/contrib/admin/__init__.py", line 24, in autodiscover
    autodiscover_modules('admin', register_to=site)
  File "/usr/local/lib/python3.6/site-packages/django/utils/module_loading.py", line 47, in autodiscover_modules
    import_module('%s.%s' % (app_config.name, module_to_search))
  File "/usr/lib64/python3.6/importlib/__init__.py", line 126, in import_module
    return _bootstrap._gcd_import(name[level:], package, level)
  File "<frozen importlib._bootstrap>", line 994, in _gcd_import
  File "<frozen importlib._bootstrap>", line 971, in _find_and_load
  File "<frozen importlib._bootstrap>", line 955, in _find_and_load_unlocked
  File "<frozen importlib._bootstrap>", line 665, in _load_unlocked
  File "<frozen importlib._bootstrap_external>", line 678, in exec_module
  File "<frozen importlib._bootstrap>", line 219, in _call_with_frames_removed
  File "/usr/local/lib/python3.6/site-packages/django/contrib/auth/admin.py", line 6, in <module>
    from django.contrib.auth.forms import (
  File "/usr/local/lib/python3.6/site-packages/django/contrib/auth/forms.py", line 213
    username = accountname + "+" + username
                                          ^
TabError: inconsistent use of tabs and spaces in indentation

/usr/local/lib/python3.6/site-packages/django/contrib/auth/forms.py changed, reloading.
Watching for file changes with StatReloader
Exception in thread django-main-thread:
Traceback (most recent call last):
  File "/usr/lib64/python3.6/threading.py", line 916, in _bootstrap_inner
    self.run()
  File "/usr/lib64/python3.6/threading.py", line 864, in run
    self._target(*self._args, **self._kwargs)
  File "/usr/local/lib/python3.6/site-packages/django/utils/autoreload.py", line 53, in wrapper
    fn(*args, **kwargs)
  File "/usr/local/lib/python3.6/site-packages/django/core/management/commands/runserver.py", line 110, in inner_run
    autoreload.raise_last_exception()
  File "/usr/local/lib/python3.6/site-packages/django/utils/autoreload.py", line 76, in raise_last_exception
    raise _exception[1]
  File "/usr/local/lib/python3.6/site-packages/django/core/management/__init__.py", line 357, in execute
    autoreload.check_errors(django.setup)()
  File "/usr/local/lib/python3.6/site-packages/django/utils/autoreload.py", line 53, in wrapper
    fn(*args, **kwargs)
  File "/usr/local/lib/python3.6/site-packages/django/__init__.py", line 24, in setup
    apps.populate(settings.INSTALLED_APPS)
  File "/usr/local/lib/python3.6/site-packages/django/apps/registry.py", line 122, in populate
    app_config.ready()
  File "/usr/local/lib/python3.6/site-packages/django/contrib/admin/apps.py", line 24, in ready
    self.module.autodiscover()
  File "/usr/local/lib/python3.6/site-packages/django/contrib/admin/__init__.py", line 24, in autodiscover
    autodiscover_modules('admin', register_to=site)
  File "/usr/local/lib/python3.6/site-packages/django/utils/module_loading.py", line 47, in autodiscover_modules
    import_module('%s.%s' % (app_config.name, module_to_search))
  File "/usr/lib64/python3.6/importlib/__init__.py", line 126, in import_module
    return _bootstrap._gcd_import(name[level:], package, level)
  File "<frozen importlib._bootstrap>", line 994, in _gcd_import
  File "<frozen importlib._bootstrap>", line 971, in _find_and_load
  File "<frozen importlib._bootstrap>", line 955, in _find_and_load_unlocked
  File "<frozen importlib._bootstrap>", line 665, in _load_unlocked
  File "<frozen importlib._bootstrap_external>", line 678, in exec_module
  File "<frozen importlib._bootstrap>", line 219, in _call_with_frames_removed
  File "/usr/local/lib/python3.6/site-packages/django/contrib/auth/admin.py", line 6, in <module>
    from django.contrib.auth.forms import (
  File "/usr/local/lib/python3.6/site-packages/django/contrib/auth/forms.py", line 213
    username = accountname+"+"+username
                                      ^
TabError: inconsistent use of tabs and spaces in indentation

/usr/local/lib/python3.6/site-packages/django/contrib/auth/forms.py changed, reloading.
Watching for file changes with StatReloader
Exception in thread django-main-thread:
Traceback (most recent call last):
  File "/usr/lib64/python3.6/threading.py", line 916, in _bootstrap_inner
    self.run()
  File "/usr/lib64/python3.6/threading.py", line 864, in run
    self._target(*self._args, **self._kwargs)
  File "/usr/local/lib/python3.6/site-packages/django/utils/autoreload.py", line 53, in wrapper
    fn(*args, **kwargs)
  File "/usr/local/lib/python3.6/site-packages/django/core/management/commands/runserver.py", line 110, in inner_run
    autoreload.raise_last_exception()
  File "/usr/local/lib/python3.6/site-packages/django/utils/autoreload.py", line 76, in raise_last_exception
    raise _exception[1]
  File "/usr/local/lib/python3.6/site-packages/django/core/management/__init__.py", line 357, in execute
    autoreload.check_errors(django.setup)()
  File "/usr/local/lib/python3.6/site-packages/django/utils/autoreload.py", line 53, in wrapper
    fn(*args, **kwargs)
  File "/usr/local/lib/python3.6/site-packages/django/__init__.py", line 24, in setup
    apps.populate(settings.INSTALLED_APPS)
  File "/usr/local/lib/python3.6/site-packages/django/apps/registry.py", line 122, in populate
    app_config.ready()
  File "/usr/local/lib/python3.6/site-packages/django/contrib/admin/apps.py", line 24, in ready
    self.module.autodiscover()
  File "/usr/local/lib/python3.6/site-packages/django/contrib/admin/__init__.py", line 24, in autodiscover
    autodiscover_modules('admin', register_to=site)
  File "/usr/local/lib/python3.6/site-packages/django/utils/module_loading.py", line 47, in autodiscover_modules
    import_module('%s.%s' % (app_config.name, module_to_search))
  File "/usr/lib64/python3.6/importlib/__init__.py", line 126, in import_module
    return _bootstrap._gcd_import(name[level:], package, level)
  File "<frozen importlib._bootstrap>", line 994, in _gcd_import
  File "<frozen importlib._bootstrap>", line 971, in _find_and_load
  File "<frozen importlib._bootstrap>", line 955, in _find_and_load_unlocked
  File "<frozen importlib._bootstrap>", line 665, in _load_unlocked
  File "<frozen importlib._bootstrap_external>", line 678, in exec_module
  File "<frozen importlib._bootstrap>", line 219, in _call_with_frames_removed
  File "/usr/local/lib/python3.6/site-packages/django/contrib/auth/admin.py", line 6, in <module>
    from django.contrib.auth.forms import (
  File "/usr/local/lib/python3.6/site-packages/django/contrib/auth/forms.py", line 212
    username = self.cleaned_data.get('username')
                                               ^
TabError: inconsistent use of tabs and spaces in indentation

/usr/local/lib/python3.6/site-packages/django/contrib/auth/forms.py changed, reloading.
Watching for file changes with StatReloader
Exception in thread django-main-thread:
Traceback (most recent call last):
  File "/usr/lib64/python3.6/threading.py", line 916, in _bootstrap_inner
    self.run()
  File "/usr/lib64/python3.6/threading.py", line 864, in run
    self._target(*self._args, **self._kwargs)
  File "/usr/local/lib/python3.6/site-packages/django/utils/autoreload.py", line 53, in wrapper
    fn(*args, **kwargs)
  File "/usr/local/lib/python3.6/site-packages/django/core/management/commands/runserver.py", line 110, in inner_run
    autoreload.raise_last_exception()
  File "/usr/local/lib/python3.6/site-packages/django/utils/autoreload.py", line 76, in raise_last_exception
    raise _exception[1]
  File "/usr/local/lib/python3.6/site-packages/django/core/management/__init__.py", line 357, in execute
    autoreload.check_errors(django.setup)()
  File "/usr/local/lib/python3.6/site-packages/django/utils/autoreload.py", line 53, in wrapper
    fn(*args, **kwargs)
  File "/usr/local/lib/python3.6/site-packages/django/__init__.py", line 24, in setup
    apps.populate(settings.INSTALLED_APPS)
  File "/usr/local/lib/python3.6/site-packages/django/apps/registry.py", line 122, in populate
    app_config.ready()
  File "/usr/local/lib/python3.6/site-packages/django/contrib/admin/apps.py", line 24, in ready
    self.module.autodiscover()
  File "/usr/local/lib/python3.6/site-packages/django/contrib/admin/__init__.py", line 24, in autodiscover
    autodiscover_modules('admin', register_to=site)
  File "/usr/local/lib/python3.6/site-packages/django/utils/module_loading.py", line 47, in autodiscover_modules
    import_module('%s.%s' % (app_config.name, module_to_search))
  File "/usr/lib64/python3.6/importlib/__init__.py", line 126, in import_module
    return _bootstrap._gcd_import(name[level:], package, level)
  File "<frozen importlib._bootstrap>", line 994, in _gcd_import
  File "<frozen importlib._bootstrap>", line 971, in _find_and_load
  File "<frozen importlib._bootstrap>", line 955, in _find_and_load_unlocked
  File "<frozen importlib._bootstrap>", line 665, in _load_unlocked
  File "<frozen importlib._bootstrap_external>", line 678, in exec_module
  File "<frozen importlib._bootstrap>", line 219, in _call_with_frames_removed
  File "/usr/local/lib/python3.6/site-packages/django/contrib/auth/admin.py", line 6, in <module>
    from django.contrib.auth.forms import (
  File "/usr/local/lib/python3.6/site-packages/django/contrib/auth/forms.py", line 212
    username = self.cleaned_data.get('username')
                                               ^
TabError: inconsistent use of tabs and spaces in indentation

/usr/local/lib/python3.6/site-packages/django/contrib/auth/forms.py changed, reloading.
Watching for file changes with StatReloader
/usr/local/lib/python3.6/site-packages/django/contrib/auth/forms.py changed, reloading.
Performing system checks...

System check identified no issues (0 silenced).

You have 25 unapplied migration(s). Your project may not work properly until you apply the migrations for app(s): django_celery_beat, django_celery_results.
Run 'python manage.py migrate' to apply them.
February 24, 2021 - 21:33:53
Django version 3.1.7, using settings 'invoicing.settings'
Starting development server at http://0.0.0.0:5100/
Quit the server with CONTROL-C.
Watching for file changes with StatReloader
[25/Feb/2021 00:28:23] code 400, message Bad request syntax ('\x03\x00\x00\x13\x0eà\x00\x00\x00\x00\x00\x01\x00\x08\x00\x03\x00\x00\x00')
[25/Feb/2021 00:28:23] "  à          " 400 -
/usr/local/lib/python3.6/site-packages/django/contrib/auth/forms.py changed, reloading.
Performing system checks...

System check identified no issues (0 silenced).

You have 25 unapplied migration(s). Your project may not work properly until you apply the migrations for app(s): django_celery_beat, django_celery_results.
Run 'python manage.py migrate' to apply them.
February 24, 2021 - 21:44:06
Django version 3.1.7, using settings 'invoicing.settings'
Starting development server at http://0.0.0.0:5100/
Quit the server with CONTROL-C.
Watching for file changes with StatReloader
Not Found: /favicon.ico
[25/Feb/2021 04:48:12] "GET /favicon.ico HTTP/1.1" 404 2103
/home/centos/invoicing/invoicing/src/invoicing/tasks.py changed, reloading.
Performing system checks...

System check identified no issues (0 silenced).

You have 25 unapplied migration(s). Your project may not work properly until you apply the migrations for app(s): django_celery_beat, django_celery_results.
Run 'python manage.py migrate' to apply them.
February 25, 2021 - 04:43:15
Django version 3.1.7, using settings 'invoicing.settings'
Starting development server at http://0.0.0.0:5100/
Quit the server with CONTROL-C.
Watching for file changes with StatReloader
Watching for file changes with StatReloader
[25/Feb/2021 19:02:56] "GET /invoice HTTP/1.1" 301 0
[25/Feb/2021 19:02:56] "GET /invoice/ HTTP/1.1" 200 26
Not Found: /favicon.ico
[25/Feb/2021 19:02:57] "GET /favicon.ico HTTP/1.1" 404 2103
Invalid HTTP_HOST header: 'clients.dev.hazdev.com.au:5200'. You may need to add 'clients.dev.hazdev.com.au' to ALLOWED_HOSTS.
Bad Request: /
[25/Feb/2021 19:58:19] "GET / HTTP/1.0" 400 64878
Invalid HTTP_HOST header: 'clients.dev.hazdev.com.au:5200'. You may need to add 'clients.dev.hazdev.com.au' to ALLOWED_HOSTS.
Bad Request: /
[25/Feb/2021 19:58:26] "GET / HTTP/1.0" 400 64839
Invalid HTTP_HOST header: 'clients.dev.hazdev.com.au:5200'. You may need to add 'clients.dev.hazdev.com.au' to ALLOWED_HOSTS.
Bad Request: /
[25/Feb/2021 19:58:29] "GET / HTTP/1.0" 400 64839
Not Found: /
[26/Feb/2021 12:38:39] "GET / HTTP/1.1" 404 2052
/home/centos/invoicing/invoicing/src/invoicing/settings.py changed, reloading.
Performing system checks...

System check identified no issues (0 silenced).

You have 25 unapplied migration(s). Your project may not work properly until you apply the migrations for app(s): django_celery_beat, django_celery_results.
Run 'python manage.py migrate' to apply them.
February 25, 2021 - 18:17:19
Django version 3.1.7, using settings 'invoicing.settings'
Starting development server at http://0.0.0.0:5100/
Quit the server with CONTROL-C.
Watching for file changes with StatReloader
Exception in thread django-main-thread:
Traceback (most recent call last):
  File "/usr/local/lib/python3.6/site-packages/django/db/backends/base/base.py", line 219, in ensure_connection
    self.connect()
  File "/usr/local/lib/python3.6/site-packages/django/utils/asyncio.py", line 26, in inner
    return func(*args, **kwargs)
  File "/usr/local/lib/python3.6/site-packages/django/db/backends/base/base.py", line 200, in connect
    self.connection = self.get_new_connection(conn_params)
  File "/usr/local/lib/python3.6/site-packages/django/utils/asyncio.py", line 26, in inner
    return func(*args, **kwargs)
  File "/usr/local/lib/python3.6/site-packages/django/db/backends/mysql/base.py", line 234, in get_new_connection
    return Database.connect(**conn_params)
  File "/usr/local/lib64/python3.6/site-packages/MySQLdb/__init__.py", line 130, in Connect
    return Connection(*args, **kwargs)
  File "/usr/local/lib64/python3.6/site-packages/MySQLdb/connections.py", line 185, in __init__
    super().__init__(*args, **kwargs2)
MySQLdb._exceptions.OperationalError: (1045, "Access denied for user 'root'@'localhost' (using password: NO)")

The above exception was the direct cause of the following exception:

Traceback (most recent call last):
  File "/usr/lib64/python3.6/threading.py", line 916, in _bootstrap_inner
    self.run()
  File "/usr/lib64/python3.6/threading.py", line 864, in run
    self._target(*self._args, **self._kwargs)
  File "/usr/local/lib/python3.6/site-packages/django/utils/autoreload.py", line 53, in wrapper
    fn(*args, **kwargs)
  File "/usr/local/lib/python3.6/site-packages/django/core/management/commands/runserver.py", line 121, in inner_run
    self.check_migrations()
  File "/usr/local/lib/python3.6/site-packages/django/core/management/base.py", line 459, in check_migrations
    executor = MigrationExecutor(connections[DEFAULT_DB_ALIAS])
  File "/usr/local/lib/python3.6/site-packages/django/db/migrations/executor.py", line 18, in __init__
    self.loader = MigrationLoader(self.connection)
  File "/usr/local/lib/python3.6/site-packages/django/db/migrations/loader.py", line 53, in __init__
    self.build_graph()
  File "/usr/local/lib/python3.6/site-packages/django/db/migrations/loader.py", line 216, in build_graph
    self.applied_migrations = recorder.applied_migrations()
  File "/usr/local/lib/python3.6/site-packages/django/db/migrations/recorder.py", line 77, in applied_migrations
    if self.has_table():
  File "/usr/local/lib/python3.6/site-packages/django/db/migrations/recorder.py", line 55, in has_table
    with self.connection.cursor() as cursor:
  File "/usr/local/lib/python3.6/site-packages/django/utils/asyncio.py", line 26, in inner
    return func(*args, **kwargs)
  File "/usr/local/lib/python3.6/site-packages/django/db/backends/base/base.py", line 259, in cursor
    return self._cursor()
  File "/usr/local/lib/python3.6/site-packages/django/db/backends/base/base.py", line 235, in _cursor
    self.ensure_connection()
  File "/usr/local/lib/python3.6/site-packages/django/utils/asyncio.py", line 26, in inner
    return func(*args, **kwargs)
  File "/usr/local/lib/python3.6/site-packages/django/db/backends/base/base.py", line 219, in ensure_connection
    self.connect()
  File "/usr/local/lib/python3.6/site-packages/django/db/utils.py", line 90, in __exit__
    raise dj_exc_value.with_traceback(traceback) from exc_value
  File "/usr/local/lib/python3.6/site-packages/django/db/backends/base/base.py", line 219, in ensure_connection
    self.connect()
  File "/usr/local/lib/python3.6/site-packages/django/utils/asyncio.py", line 26, in inner
    return func(*args, **kwargs)
  File "/usr/local/lib/python3.6/site-packages/django/db/backends/base/base.py", line 200, in connect
    self.connection = self.get_new_connection(conn_params)
  File "/usr/local/lib/python3.6/site-packages/django/utils/asyncio.py", line 26, in inner
    return func(*args, **kwargs)
  File "/usr/local/lib/python3.6/site-packages/django/db/backends/mysql/base.py", line 234, in get_new_connection
    return Database.connect(**conn_params)
  File "/usr/local/lib64/python3.6/site-packages/MySQLdb/__init__.py", line 130, in Connect
    return Connection(*args, **kwargs)
  File "/usr/local/lib64/python3.6/site-packages/MySQLdb/connections.py", line 185, in __init__
    super().__init__(*args, **kwargs2)
django.db.utils.OperationalError: (1045, "Access denied for user 'root'@'localhost' (using password: NO)")

/home/centos/invoicing/invoicing/src/invoicing/settings.py changed, reloading.
Performing system checks...

System check identified no issues (0 silenced).
Traceback (most recent call last):
  File "manage.py", line 22, in <module>
    main()
  File "manage.py", line 18, in main
    execute_from_command_line(sys.argv)
  File "/usr/local/lib/python3.6/site-packages/django/core/management/__init__.py", line 401, in execute_from_command_line
    utility.execute()
  File "/usr/local/lib/python3.6/site-packages/django/core/management/__init__.py", line 345, in execute
    settings.INSTALLED_APPS
  File "/usr/local/lib/python3.6/site-packages/django/conf/__init__.py", line 82, in __getattr__
    self._setup(name)
  File "/usr/local/lib/python3.6/site-packages/django/conf/__init__.py", line 69, in _setup
    self._wrapped = Settings(settings_module)
  File "/usr/local/lib/python3.6/site-packages/django/conf/__init__.py", line 170, in __init__
    mod = importlib.import_module(self.SETTINGS_MODULE)
  File "/usr/lib64/python3.6/importlib/__init__.py", line 126, in import_module
    return _bootstrap._gcd_import(name[level:], package, level)
  File "<frozen importlib._bootstrap>", line 994, in _gcd_import
  File "<frozen importlib._bootstrap>", line 971, in _find_and_load
  File "<frozen importlib._bootstrap>", line 941, in _find_and_load_unlocked
  File "<frozen importlib._bootstrap>", line 219, in _call_with_frames_removed
  File "<frozen importlib._bootstrap>", line 994, in _gcd_import
  File "<frozen importlib._bootstrap>", line 971, in _find_and_load
  File "<frozen importlib._bootstrap>", line 955, in _find_and_load_unlocked
  File "<frozen importlib._bootstrap>", line 665, in _load_unlocked
  File "<frozen importlib._bootstrap_external>", line 678, in exec_module
  File "<frozen importlib._bootstrap>", line 219, in _call_with_frames_removed
  File "/home/centos/invoicing/invoicing/src/invoicing/__init__.py", line 1, in <module>
    from .celery import app as celery_app 
  File "/home/centos/invoicing/invoicing/src/invoicing/celery.py", line 43, in <module>
    file_path   = os.path.join(os.path.dirname(settings.BASE_DIR), "src")
  File "/usr/local/lib/python3.6/site-packages/django/conf/__init__.py", line 82, in __getattr__
    self._setup(name)
  File "/usr/local/lib/python3.6/site-packages/django/conf/__init__.py", line 69, in _setup
    self._wrapped = Settings(settings_module)
  File "/usr/local/lib/python3.6/site-packages/django/conf/__init__.py", line 170, in __init__
    mod = importlib.import_module(self.SETTINGS_MODULE)
  File "/usr/lib64/python3.6/importlib/__init__.py", line 126, in import_module
    return _bootstrap._gcd_import(name[level:], package, level)
  File "/home/centos/invoicing/invoicing/src/invoicing/settings.py", line 29
    ALLOWED_HOSTS = [13.211.97.129]
                             ^
SyntaxError: invalid syntax
